## Возбуждение исключений (raise)
# Исключения являются не только механизмом обработки ошибок, но и удобным средством управления потоком выполнения. Так, необходимое исключение можно возбудить вручную, когда это необходимо, используя конструкцию raise.

# raise
# raise exception(args)  # явное указание класса возбуждаемого исключения

# # или

# raise                  # 1) повторное возбуждение активного исключения (re-raise)
#                        #    внутри блока except
#                        # 2) 'TypeError' по умолчанию


# Возбуждаемое исключение может быть как встроенным (если соответствует по смыслу), так и пользовательским (создаваемым самостоятельно).

# Повторный проброс исключений в Python

# Возникшие когда-либо исключения продолжают перемещаться к вызывающим методам, пока не будут обработаны. Хотя вы можете добавить исключающее предложение, которое может просто вызывать raise без каких-либо аргументов. Это приведет к пересмотру исключения.


try:
    # Преднамеренно бросить исключение.
    raise Exception('I learn Python!')
except:
    print("Entered in except.")
    # Возобновить исключение.
    raise
# Вывод:

# Entered in except.
# Traceback (most recent call last):
#   File "python", line 3, in 
# Exception: I learn Python!


# Обработка нескольких исключений одним блоком Except
# использовать исключение без упоминания какого-либо атрибута исключения.

try:
    file = open('input-file', 'open mode')
except:
    raise


# Этот метод может быть полезен, если вы не имеете ни малейшего представления об исключении, которое может выдать ваша программа.

# Использование raise для управления потоком выполнения

MIN = 1
MAX = 10

try:
    x = int(input("Введите целое число от {} до {}: ".format(MIN, MAX)))

    if not MIN <= x <= MAX:
        # Возбудив исключение, его можно будет обработать в except
        # вместе с другими похожими исключениями
        raise ValueError("Число лежит вне интервала [{}; {}]!".format(MIN, MAX))

    print("Спасибо!")
except ValueError as err:  # 'err' содержит ссылку на исключение
    print("Будьте внимательны:", err)

